/usr/local/lib/python3.10/site-packages/oauth2_provider/__init__.py:1: UserWarning: pkg_resources is deprecated as an API. See https://setuptools.pypa.io/en/latest/pkg_resources.html. The pkg_resources package is slated for removal as early as 2025-11-30. Refrain from using this package or pin to Setuptools<81.
  import pkg_resources
UserWarning: You have an incompatible version of 'pyarrow' installed (21.0.0), please install a version that adheres to: 'pyarrow<19.0.0; extra == "pandas"'
[2025-08-10 23:23:53,856: INFO/MainProcess] beat: Starting...
[2025-08-10 23:25:59,428: INFO/MainProcess] DatabaseScheduler: Schedule changed.
/usr/local/lib/python3.10/site-packages/oauth2_provider/__init__.py:1: UserWarning: pkg_resources is deprecated as an API. See https://setuptools.pypa.io/en/latest/pkg_resources.html. The pkg_resources package is slated for removal as early as 2025-11-30. Refrain from using this package or pin to Setuptools<81.
  import pkg_resources
UserWarning: You have an incompatible version of 'pyarrow' installed (21.0.0), please install a version that adheres to: 'pyarrow<19.0.0; extra == "pandas"'
[2025-08-11 08:49:51,439: INFO/MainProcess] beat: Starting...
/usr/local/lib/python3.10/site-packages/oauth2_provider/__init__.py:1: UserWarning: pkg_resources is deprecated as an API. See https://setuptools.pypa.io/en/latest/pkg_resources.html. The pkg_resources package is slated for removal as early as 2025-11-30. Refrain from using this package or pin to Setuptools<81.
  import pkg_resources
UserWarning: You have an incompatible version of 'pyarrow' installed (21.0.0), please install a version that adheres to: 'pyarrow<19.0.0; extra == "pandas"'
[2025-08-11 08:54:09,090: INFO/MainProcess] beat: Starting...
[2025-08-11 08:59:10,341: INFO/MainProcess] DatabaseScheduler: Schedule changed.
[2025-08-11 23:01:13,478: ERROR/MainProcess] Database gave error: OperationalError('could not translate host name "db" to address: Temporary failure in name resolution\n')
Traceback (most recent call last):
  File "/usr/local/lib/python3.10/site-packages/django/db/backends/base/base.py", line 282, in ensure_connection
    self.connect()
  File "/usr/local/lib/python3.10/site-packages/django/utils/asyncio.py", line 26, in inner
    return func(*args, **kwargs)
  File "/usr/local/lib/python3.10/site-packages/django/db/backends/base/base.py", line 263, in connect
    self.connection = self.get_new_connection(conn_params)
  File "/usr/local/lib/python3.10/site-packages/django/utils/asyncio.py", line 26, in inner
    return func(*args, **kwargs)
  File "/usr/local/lib/python3.10/site-packages/django/db/backends/postgresql/base.py", line 215, in get_new_connection
    connection = Database.connect(**conn_params)
  File "/usr/local/lib/python3.10/site-packages/psycopg2/__init__.py", line 122, in connect
    conn = _connect(dsn, connection_factory=connection_factory, **kwasync)
psycopg2.OperationalError: could not translate host name "db" to address: Temporary failure in name resolution


The above exception was the direct cause of the following exception:

Traceback (most recent call last):
  File "/usr/local/lib/python3.10/site-packages/django_celery_beat/schedulers.py", line 417, in schedule_changed
    last, ts = self._last_timestamp, self.Changes.last_change()
  File "/usr/local/lib/python3.10/site-packages/django_celery_beat/models.py", line 427, in last_change
    return cls.objects.get(ident=1).last_update
  File "/usr/local/lib/python3.10/site-packages/django/db/models/manager.py", line 85, in manager_method
    return getattr(self.get_queryset(), name)(*args, **kwargs)
  File "/usr/local/lib/python3.10/site-packages/django/db/models/query.py", line 646, in get
    num = len(clone)
  File "/usr/local/lib/python3.10/site-packages/django/db/models/query.py", line 376, in __len__
    self._fetch_all()
  File "/usr/local/lib/python3.10/site-packages/django/db/models/query.py", line 1867, in _fetch_all
    self._result_cache = list(self._iterable_class(self))
  File "/usr/local/lib/python3.10/site-packages/django/db/models/query.py", line 87, in __iter__
    results = compiler.execute_sql(
  File "/usr/local/lib/python3.10/site-packages/django/db/models/sql/compiler.py", line 1396, in execute_sql
    cursor = self.connection.cursor()
  File "/usr/local/lib/python3.10/site-packages/django/utils/asyncio.py", line 26, in inner
    return func(*args, **kwargs)
  File "/usr/local/lib/python3.10/site-packages/django/db/backends/base/base.py", line 323, in cursor
    return self._cursor()
  File "/usr/local/lib/python3.10/site-packages/django/db/backends/base/base.py", line 299, in _cursor
    self.ensure_connection()
  File "/usr/local/lib/python3.10/site-packages/django/utils/asyncio.py", line 26, in inner
    return func(*args, **kwargs)
  File "/usr/local/lib/python3.10/site-packages/django/db/backends/base/base.py", line 281, in ensure_connection
    with self.wrap_database_errors:
  File "/usr/local/lib/python3.10/site-packages/django/db/utils.py", line 91, in __exit__
    raise dj_exc_value.with_traceback(traceback) from exc_value
  File "/usr/local/lib/python3.10/site-packages/django/db/backends/base/base.py", line 282, in ensure_connection
    self.connect()
  File "/usr/local/lib/python3.10/site-packages/django/utils/asyncio.py", line 26, in inner
    return func(*args, **kwargs)
  File "/usr/local/lib/python3.10/site-packages/django/db/backends/base/base.py", line 263, in connect
    self.connection = self.get_new_connection(conn_params)
  File "/usr/local/lib/python3.10/site-packages/django/utils/asyncio.py", line 26, in inner
    return func(*args, **kwargs)
  File "/usr/local/lib/python3.10/site-packages/django/db/backends/postgresql/base.py", line 215, in get_new_connection
    connection = Database.connect(**conn_params)
  File "/usr/local/lib/python3.10/site-packages/psycopg2/__init__.py", line 122, in connect
    conn = _connect(dsn, connection_factory=connection_factory, **kwasync)
django.db.utils.OperationalError: could not translate host name "db" to address: Temporary failure in name resolution

