/usr/local/lib/python3.10/site-packages/polymorphic/__init__.py:9: UserWarning: pkg_resources is deprecated as an API. See https://setuptools.pypa.io/en/latest/pkg_resources.html. The pkg_resources package is slated for removal as early as 2025-11-30. Refrain from using this package or pin to Setuptools<81.
  import pkg_resources
/usr/local/lib/python3.10/site-packages/oauth2_provider/__init__.py:1: UserWarning: pkg_resources is deprecated as an API. See https://setuptools.pypa.io/en/latest/pkg_resources.html. The pkg_resources package is slated for removal as early as 2025-11-30. Refrain from using this package or pin to Setuptools<81.
  import pkg_resources
UserWarning: You have an incompatible version of 'pyarrow' installed (21.0.0), please install a version that adheres to: 'pyarrow<19.0.0; extra == "pandas"'
SecurityWarning: You're running the worker with superuser privileges: this is
absolutely not recommended!

Please specify a different user using the --uid option.

User information: uid=0 euid=0 gid=0 egid=0

[2025-08-10 10:57:19,052: INFO/MainProcess] Connected to redis://redis:6379/0
[2025-08-10 10:57:19,055: INFO/MainProcess] mingle: searching for neighbors
[2025-08-10 10:57:20,064: INFO/MainProcess] mingle: all alone
[2025-08-10 10:57:20,083: INFO/MainProcess] celery@8824640bf3d7 ready.
/usr/local/lib/python3.10/site-packages/oauth2_provider/__init__.py:1: UserWarning: pkg_resources is deprecated as an API. See https://setuptools.pypa.io/en/latest/pkg_resources.html. The pkg_resources package is slated for removal as early as 2025-11-30. Refrain from using this package or pin to Setuptools<81.
  import pkg_resources
UserWarning: You have an incompatible version of 'pyarrow' installed (21.0.0), please install a version that adheres to: 'pyarrow<19.0.0; extra == "pandas"'
SecurityWarning: You're running the worker with superuser privileges: this is
absolutely not recommended!

Please specify a different user using the --uid option.

User information: uid=0 euid=0 gid=0 egid=0

[2025-08-10 11:10:31,830: INFO/MainProcess] Connected to redis://redis:6379/0
[2025-08-10 11:10:31,832: INFO/MainProcess] mingle: searching for neighbors
[2025-08-10 11:10:32,840: INFO/MainProcess] mingle: all alone
[2025-08-10 11:10:32,858: INFO/MainProcess] celery@e8ad00004937 ready.
/usr/local/lib/python3.10/site-packages/oauth2_provider/__init__.py:1: UserWarning: pkg_resources is deprecated as an API. See https://setuptools.pypa.io/en/latest/pkg_resources.html. The pkg_resources package is slated for removal as early as 2025-11-30. Refrain from using this package or pin to Setuptools<81.
  import pkg_resources
UserWarning: You have an incompatible version of 'pyarrow' installed (21.0.0), please install a version that adheres to: 'pyarrow<19.0.0; extra == "pandas"'
SecurityWarning: You're running the worker with superuser privileges: this is
absolutely not recommended!

Please specify a different user using the --uid option.

User information: uid=0 euid=0 gid=0 egid=0

[2025-08-10 11:20:46,020: INFO/MainProcess] Connected to redis://redis:6379/0
[2025-08-10 11:20:46,022: INFO/MainProcess] mingle: searching for neighbors
[2025-08-10 11:20:47,028: INFO/MainProcess] mingle: all alone
[2025-08-10 11:20:47,057: INFO/MainProcess] celery@4ed7f60e20b1 ready.
[2025-08-10 11:22:32,320: INFO/MainProcess] Task apps.core.tasks.retrieve_github_eo_data[12808296-2c19-4f00-83e8-16cd95b18a86] received
[2025-08-10 11:22:32,322: INFO/ForkPoolWorker-15]  Retrieve EO Data
[2025-08-10 11:22:33,653: WARNING/ForkPoolWorker-15] Creating 'source-github' virtual environment with command 
'/usr/local/bin/python3.10 -m venv /app/.venv-source-github'
[2025-08-10 11:22:36,009: WARNING/ForkPoolWorker-15] Installing 'source-github' into virtual environment '/app/.venv-source-github' 
with command 'pip --python /app/.venv-source-github/bin/python install 
airbyte-source-github'...
[2025-08-10 11:22:55,611: WARNING/ForkPoolWorker-15] Connector 'source-github' installed successfully!
For more information, see the source-github documentation:
https://docs.airbyte.com/integrations/sources/github#reference
[2025-08-10 11:22:55,620: WARNING/ForkPoolWorker-15] Writing PyAirbyte logs to file: /tmp/airbyte/logs/2025-08-10/airbyte-log-K2A5SW447.log
[2025-08-10 11:22:55,620: WARNING/ForkPoolWorker-15] Writing `source-github` logs to file: /tmp/airbyte/logs/source-github/source-github-log-K2A5SW44R.log
[2025-08-10 11:22:58,256: ERROR/ForkPoolWorker-15] Task apps.core.tasks.retrieve_github_eo_data[12808296-2c19-4f00-83e8-16cd95b18a86] raised unexpected: AirbyteConnectorCheckFailedError(guidance='Please review the log file for more information.', help_url='https://docs.airbyte.com/integrations/sources/github', log_text=None, log_file=PosixPath('/tmp/airbyte/logs/source-github/source-github-log-K2A5SW44R.log'), print_full_log=False, context={'failure_reason': '\'AttributeError("\\\'NoneType\\\' object has no attribute \\\'get\\\'")\''}, message=None, original_exception=None, connector_name='source-github')
Traceback (most recent call last):
  File "/usr/local/lib/python3.10/site-packages/celery/app/trace.py", line 453, in trace_task
    R = retval = fun(*args, **kwargs)
  File "/usr/local/lib/python3.10/site-packages/celery/app/trace.py", line 736, in __protected_call__
    return self.run(*args, **kwargs)
  File "/app/src/apps/core/tasks.py", line 46, in retrieve_github_eo_data
    ExtractEO().run()
  File "/app/src/apps/core/extract_github/extract_eo.py", line 21, in __init__
    super().__init__()
  File "/app/src/apps/core/extract_github/extract_base.py", line 89, in __init__
    self.source.check()
  File "/usr/local/lib/python3.10/site-packages/airbyte/_connector_base.py", line 357, in check
    raise exc.AirbyteConnectorCheckFailedError(
airbyte.exceptions.AirbyteConnectorCheckFailedError: Connector check failed. (AirbyteConnectorCheckFailedError)
------------------------------------------------------------
AirbyteConnectorCheckFailedError: Connector check failed.
    Please review the log file for more information.
    More info: https://docs.airbyte.com/integrations/sources/github
    Connector Name: 'source-github'
    Failure Reason: '\'AttributeError("\\\'NoneType\\\' object has no attribute \\\'get\\\'")\''
    Log file: /tmp/airbyte/logs/source-github/source-github-log-K2A5SW44R.log
[2025-08-10 11:23:24,702: INFO/MainProcess] Task apps.core.tasks.retrieve_github_eo_data[99a865df-591f-4976-b1fa-f2c37e6bdbeb] received
[2025-08-10 11:23:24,704: INFO/ForkPoolWorker-15]  Retrieve EO Data
[2025-08-10 11:23:24,782: WARNING/ForkPoolWorker-15] Writing `source-github` logs to file: /tmp/airbyte/logs/source-github/source-github-log-K2A5TRKE3.log
[2025-08-10 11:23:27,535: ERROR/ForkPoolWorker-15] Task apps.core.tasks.retrieve_github_eo_data[99a865df-591f-4976-b1fa-f2c37e6bdbeb] raised unexpected: AirbyteConnectorCheckFailedError(guidance='Please review the log file for more information.', help_url='https://docs.airbyte.com/integrations/sources/github', log_text=None, log_file=PosixPath('/tmp/airbyte/logs/source-github/source-github-log-K2A5TRKE3.log'), print_full_log=False, context={'failure_reason': '\'AttributeError("\\\'NoneType\\\' object has no attribute \\\'get\\\'")\''}, message=None, original_exception=None, connector_name='source-github')
Traceback (most recent call last):
  File "/usr/local/lib/python3.10/site-packages/celery/app/trace.py", line 453, in trace_task
    R = retval = fun(*args, **kwargs)
  File "/usr/local/lib/python3.10/site-packages/celery/app/trace.py", line 736, in __protected_call__
    return self.run(*args, **kwargs)
  File "/app/src/apps/core/tasks.py", line 46, in retrieve_github_eo_data
    ExtractEO().run()
  File "/app/src/apps/core/extract_github/extract_eo.py", line 21, in __init__
    super().__init__()
  File "/app/src/apps/core/extract_github/extract_base.py", line 89, in __init__
    self.source.check()
  File "/usr/local/lib/python3.10/site-packages/airbyte/_connector_base.py", line 357, in check
    raise exc.AirbyteConnectorCheckFailedError(
airbyte.exceptions.AirbyteConnectorCheckFailedError: Connector check failed. (AirbyteConnectorCheckFailedError)
------------------------------------------------------------
AirbyteConnectorCheckFailedError: Connector check failed.
    Please review the log file for more information.
    More info: https://docs.airbyte.com/integrations/sources/github
    Connector Name: 'source-github'
    Failure Reason: '\'AttributeError("\\\'NoneType\\\' object has no attribute \\\'get\\\'")\''
    Log file: /tmp/airbyte/logs/source-github/source-github-log-K2A5TRKE3.log
